Workbook

Sheet Cover
B2: DETAILED PROJECT REPORT (DPR)
B3: TERM LOAN CREDIT APPRAISAL DOSSIER
B5: PROJECT TITLE & PURPOSE
B6: Project Name | C6: Hotel Case Study
B7: Project Purpose / Activity | C7: Setting up a 125-Room Premium Business Hotel with Multi-Cuisine Restaurant & Banquet Facilities
B8: Project / Unit Location | C8: Survey No. 118, Outer Ring Road, Near IT Corridor, Bengaluru, Karnataka - 560103
B10: CREDIT FACILITIES SOUGHT
B11: Term Loan Facility | C11: Term Loan of Rs. 70.00 Crore
B12: Working Capital Facility | C12: Working Capital / CC Limit of Rs. 5.00 Crore (Proposed)
B13: Total Credit Facility | C13: Rs. 75.00 Crore
B15: LENDER / BANK SUBMISSION
B16: Submitted To (Bank Name) | C16: State Bank of India
B17: Branch Name | C17: Commercial & Industrial Finance Branch
B18: Branch Address | C18: BKC Financial District, Bandra (East), Mumbai - 400051
B20: BORROWING ENTITY DETAILS
B21: Name of the Entity | C21: Grand Horizon Hospitality LLP
B22: Constitution | C22: Limited Liability Partnership (LLP)
B23: Registered Office Address | C23: 124 Hospitality Boulevard, Mumbai
B24: Date of Commencement | C24: 15-Aug-2026
B25: Permanent Account Number (PAN) | C25: AAAFG1234H
B26: GST Registration Number (GSTIN) | C26: 06AAAFG1234H1Z5
B27: Udyam (MSME) Registration | C27: UDYAM-MH-03-0012345 (Medium)
B28: Corporate Identity Number (CIN) | C28: U55101MH2024PTC123456
B29: Statutory Licences | C29: FSSAI, Star Classification, Fire NOC, Pollution Consent
B31: PROMOTER / MANAGEMENT DETAILS
B32: Promoter / Managing Director | C32: Rajesh V. Sharma
B33: Promoter Shareholding & Net Worth | C33: 65.0% Equity | Net Worth: ₹ 95.00 Cr
B34: Authorised Signatory | C34: Rajesh V. Sharma (Managing Director)
B35: Promoter CIBIL / Credit Score | C35: 785 (Excellent Track Record)

Sheet Assumptions
B1: DETAILED PROJECT REPORT - FINANCIAL MODEL ASSUMPTIONS
B2: All amounts in ₹ in Crore unless stated otherwise. Input cells in blue font with light yellow fill.
B4: 1. PROJECT TIMELINE & CAPACITY
B5: Construction Start Financial Year (FY) | C5: 2024
B6: Construction Phasing Period (Quarters) | C6: 8
B7: Operating Projection Horizon (Years) | C7: 10
B8: Hotel Room Capacity (Keys) | C8: 125
B9: Operating Days per Calendar Year | C9: 365
B11: 2. TARIFF & OCCUPANCY PARAMETERS
B12: Initial Room Tariff in Year 1 (₹ per room/day) | C12: 10000
B13: Annual Tariff Escalation Rate | C13: 0.015
B14: Year 1 Occupancy Rate | C14: 0.65
B15: Annual Occupancy Ramp-Up Rate | C15: 0.025
B16: Maximum Occupancy Cap | C16: 0.8
B17: Rooms Revenue Share of Total Revenue | C17: 0.55
B18: F&B Revenue Share of Total Revenue | C18: 0.3
B19: Other Sources Share of Total Revenue | C19: 0.15
B21: 3. OPERATING EXPENDITURE BENCHMARKS (% OF REVENUE)
B22: F&B Consumables Cost (% of Total Revenue) | C22: 0.075
B23: Employee Costs (% of Total Revenue) | C23: 0.2
B24: Power & Fuel Expenses (% of Total Revenue) | C24: 0.06
B25: Other Variable Operating Expenses (% of Total Revenue) | C25: 0.04
B26: Management / Service Fees (% of Room Revenue) | C26: 0.05
B27: Administrative & General Expenses (% of Year 1 Rev) | C27: 0.2
B28: Annual Admin Expenses Inflation Rate | C28: 0.1
B30: 4. DEPRECIATION, TAXATION & FINANCING PARAMETERS
B31: Useful Asset Life: Hotel Building (Years) | C31: 40
B32: Useful Asset Life: Plant & Equipment (Years) | C32: 15
B33: Applicable Corporate Tax Rate | C33: 0.33
B34: Term Loan Interest Rate (p.a.) | C34: 0.1
B35: Term Loan Repayment Tenure (Years) | C35: 10
B36: Total Installments (Quarterly / Monthly) | C36: 120
B38: 5. ANNUAL TERM LOAN PRINCIPAL REPAYMENT SCHEDULE (% OF LOAN)
C39: Y1 | D39: Y2 | E39: Y3 | F39: Y4 | G39: Y5 | H39: Y6 | I39: Y7 | J39: Y8 | K39: Y9 | L39: Y10
B40: Repayment Percentage of Total Term Loan | C40: 0.025 | D40: 0.05 | E40: 0.075 | F40: 0.1 | G40: 0.125 | H40: 0.125 | I40: 0.125 | J40: 0.125 | K40: 0.125 | L40: 0.125
B42: 6. PROJECT COST ITEMS, PROMOTER MARGINS & QUARTERLY PHASING (₹ in Crore)
B43: Cost Item Description | C43: Estimated Cost (₹ in Crore) | D43: Margin % | E43: Category | F43: Bldg Share % | G43: Q1 | H43: Q2 | I43: Q3 | J43: Q4 | K43: Q5 | L43: Q6 | M43: Q7 | N43: Q8
B44: Cost of Land [already acquired by the Company] | C44: 20 | D44: 1 | E44: land | F44: 0.5 | G44: 1 | H44: 0 | I44: 0 | J44: 0 | K44: 0 | L44: 0 | M44: 0 | N44: 0
B45: Cost of Approvals / Premiums & Regulatory Costs | C45: 10 | D45: 0.5 | E45: building | F45: 0.5 | G45: 0.25 | H45: 0.5 | I45: 0.1 | J45: 0 | K45: 0 | L45: 0 | M45: 0.1 | N45: 0
B46: Cost of Construction of the Hotel Building | C46: 40 | D46: 0.3 | E46: building | F46: 0.5 | G46: 0.1 | H46: 0.2 | I46: 0.3 | J46: 0.35 | K46: 0.05 | L46: 0 | M46: 0 | N46: 0
...

Sheet Project Cost & Finance
B1: PROJECT COST BREAKDOWN, FINANCING PLAN & DRAWDOWN SCHEDULE (₹ in Crore)
B2: All figures in ₹ in Crore. Fully dynamic formulas linked to Assumptions sheet.
B4: 1. PROJECT COST BREAKDOWN & FINANCING PLAN
B5: Cost Component / Particulars | C5: Estimated Cost | D5: Promoter Margin % | E5: Promoter Contribution | F5: Bank Finance | G5: Promoter Share % | H5: Bank Share %
B6: =Assumptions!B44 | C6: =Assumptions!C44 | D6: =Assumptions!D44 | E6: =C6*D6 | F6: =C6-E6 | G6: =E6/C6 | H6: =F6/C6
B7: =Assumptions!B45 | C7: =Assumptions!C45 | D7: =Assumptions!D45 | E7: =C7*D7 | F7: =C7-E7 | G7: =E7/C7 | H7: =F7/C7
B8: =Assumptions!B46 | C8: =Assumptions!C46 | D8: =Assumptions!D46 | E8: =C8*D8 | F8: =C8-E8 | G8: =E8/C8 | H8: =F8/C8
B9: =Assumptions!B47 | C9: =Assumptions!C47 | D9: =Assumptions!D47 | E9: =C9*D9 | F9: =C9-E9 | G9: =E9/C9 | H9: =F9/C9
B10: =Assumptions!B48 | C10: =Assumptions!C48 | D10: =Assumptions!D48 | E10: =C10*D10 | F10: =C10-E10 | G10: =E10/C10 | H10: =F10/C10
B11: Core Project Cost [A] | C11: =SUM(C6:C10) | D11: - | E11: =SUM(E6:E10) | F11: =SUM(F6:F10) | G11: =E11/C11 | H11: =F11/C11
B12: Interest During Construction (IDC) [B] | C12: =K36 | D12: 1 | E12: =C12 | F12: 0 | G12: 1 | H12: 0
B13: Total Project Cost [A + B] | C13: =C11+C12 | D13: - | E13: =E11+E12 | F13: =F11+F12 | G13: =E13/C13 | H13: =F13/C13
B14: Debt : Equity Ratio (Bank Finance / Promoters Contribution) | C14: =F13/E13
B16: 2. QUARTERLY CAPITAL EXPENDITURE PHASING (₹ in Crore)
B17: Cost Item Description | C17: Q1 | D17: Q2 | E17: Q3 | F17: Q4 | G17: Q5 | H17: Q6 | I17: Q7 | J17: Q8 | K17: Total Capex
B18: =Assumptions!B44 | C18: =Assumptions!$C$44*Assumptions!G$44 | D18: =Assumptions!$C$44*Assumptions!H$44 | E18: =Assumptions!$C$44*Assumptions!I$44 | F18: =Assumptions!$C$44*Assumptions!J$44 | G18: =Assumptions!$C$44*Assumptions!K$44 | H18: =Assumptions!$C$44*Assumptions!L$44 | I18: =Assumptions!$C$44*Assumptions!M$44 | J18: =Assumptions!$C$44*Assumptions!N$44 | K18: =SUM(C18:J18)
B19: =Assumptions!B45 | C19: =Assumptions!$C$45*Assumptions!G$45 | D19: =Assumptions!$C$45*Assumptions!H$45 | E19: =Assumptions!$C$45*Assumptions!I$45 | F19: =Assumptions!$C$45*Assumptions!J$45 | G19: =Assumptions!$C$45*Assumptions!K$45 | H19: =Assumptions!$C$45*Assumptions!L$45 | I19: =Assumptions!$C$45*Assumptions!M$45 | J19: =Assumptions!$C$45*Assumptions!N$45 | K19: =SUM(C19:J19)
B20: =Assumptions!B46 | C20: =Assumptions!$C$46*Assumptions!G$46 | D20: =Assumptions!$C$46*Assumptions!H$46 | E20: =Assumptions!$C$46*Assumptions!I$46 | F20: =Assumptions!$C$46*Assumptions!J$46 | G20: =Assumptions!$C$46*Assumptions!K$46 | H20: =Assumptions!$C$46*Assumptions!L$46 | I20: =Assumptions!$C$46*Assumptions!M$46 | J20: =Assumptions!$C$46*Assumptions!N$46 | K20: =SUM(C20:J20)
B21: =Assumptions!B47 | C21: =Assumptions!$C$47*Assumptions!G$47 | D21: =Assumptions!$C$47*Assumptions!H$47 | E21: =Assumptions!$C$47*Assumptions!I$47 | F21: =Assumptions!$C$47*Assumptions!J$47 | G21: =Assumptions!$C$47*Assumptions!K$47 | H21: =Assumptions!$C$47*Assumptions!L$47 | I21: =Assumptions!$C$47*Assumptions!M$47 | J21: =Assumptions!$C$47*Assumptions!N$47 | K21: =SUM(C21:J21)
B22: Total Capex Incurred per Quarter | C22: =SUM(C18:C21) | D22: =SUM(D18:D21) | E22: =SUM(E18:E21) | F22: =SUM(F18:F21) | G22: =SUM(G18:G21) | H22: =SUM(H18:H21) | I22: =SUM(I18:I21) | J22: =SUM(J18:J21) | K22: =SUM(C22:J22)
B24: 3. QUARTERLY BANK LOAN DRAWDOWN & IDC COMPUTATION (₹ in Crore)
B25: Item Bank Loan Drawdown | C25: Q1 | D25: Q2 | E25: Q3 | F25: Q4 | G25: Q5 | H25: Q6 | I25: Q7 | J25: Q8 | K25: Total Bank Loan
B26: =Assumptions!B44 | C26: =C18*(1-Assumptions!$D$44) | D26: =D18*(1-Assumptions!$D$44) | E26: =E18*(1-Assumptions!$D$44) | F26: =F18*(1-Assumptions!$D$44) | G26: =G18*(1-Assumptions!$D$44) | H26: =H18*(1-Assumptions!$D$44) | I26: =I18*(1-Assumptions!$D$44) | J26: =J18*(1-Assumptions!$D$44) | K26: =SUM(C26:J26)
B27: =Assumptions!B45 | C27: =C19*(1-Assumptions!$D$45) | D27: =D19*(1-Assumptions!$D$45) | E27: =E19*(1-Assumptions!$D$45) | F27: =F19*(1-Assumptions!$D$45) | G27: =G19*(1-Assumptions!$D$45) | H27: =H19*(1-Assumptions!$D$45) | I27: =I19*(1-Assumptions!$D$45) | J27: =J19*(1-Assumptions!$D$45) | K27: =SUM(C27:J27)
B28: =Assumptions!B46 | C28: =C20*(1-Assumptions!$D$46) | D28: =D20*(1-Assumptions!$D$46) | E28: =E20*(1-Assumptions!$D$46) | F28: =F20*(1-Assumptions!$D$46) | G28: =G20*(1-Assumptions!$D$46) | H28: =H20*(1-Assumptions!$D$46) | I28: =I20*(1-Assumptions!$D$46) | J28: =J20*(1-Assumptions!$D$46) | K28: =SUM(C28:J28)
B29: =Assumptions!B47 | C29: =C21*(1-Assumptions!$D$47) | D29: =D21*(1-Assumptions!$D$47) | E29: =E21*(1-Assumptions!$D$47) | F29: =F21*(1-Assumptions!$D$47) | G29: =G21*(1-Assumptions!$D$47) | H29: =H21*(1-Assumptions!$D$47) | I29: =I21*(1-Assumptions!$D$47) | J29: =J21*(1-Assumptions!$D$47) | K29: =SUM(C29:J29)
B30: Total Bank Loan Drawn in Quarter | C30: =SUM(C26:C29) | D30: =SUM(D26:D29) | E30: =SUM(E26:E29) | F30: =SUM(F26:F29) | G30: =SUM(G26:G29) | H30: =SUM(H26:H29) | I30: =SUM(I26:I29) | J30: =SUM(J26:J29) | K30: =SUM(C30:J30)
B32: Opening Loan Balance | C32: 0 | D32: =C34 | E32: =D34 | F32: =E34 | G32: =F34 | H32: =G34 | I32: =H34 | J32: =I34 | K32: -
B33: Add: Bank Loan Drawdown during Quarter | C33: =C30 | D33: =D30 | E33: =E30 | F33: =F30 | G33: =G30 | H33: =H30 | I33: =I30 | J33: =J30 | K33: =SUM(C33:J33)
B34: Closing Loan Balance | C34: =C32+C33 | D34: =D32+D33 | E34: =E32+E33 | F34: =F32+F33 | G34: =G32+G33 | H34: =H32+H33 | I34: =I32+I33 | J34: =J32+J33 | K34: =J34
B35: Average Loan Balance during Quarter | C35: =(C32+C34)/2 | D35: =(D32+D34)/2 | E35: =(E32+E34)/2 | F35: =(F32+F34)/2 | G35: =(G32+G34)/2 | H35: =(H32+H34)/2 | I35: =(I32+I34)/2 | J35: =(J32+J34)/2 | K35: -
B36: Interest During Construction (IDC) for Quarter | C36: =C35*Assumptions!$C$34*(3/12) | D36: =D35*Assumptions!$C$34*(3/12) | E36: =E35*Assumptions!$C$34*(3/12) | F36: =F35*Assumptions!$C$34*(3/12) | G36: =G35*Assumptions!$C$34*(3/12) | H36: =H35*Assumptions!$C$34*(3/12) | I36: =I35*Assumptions!$C$34*(3/12) | J36: =J35*Assumptions!$C$34*(3/12) | K36: =SUM(C36:J36)

Sheet Depreciation
B1: FIXED ASSET CAPITALISATION & DEPRECIATION SCHEDULE (₹ in Crore)
B2: Straight Line Method (SLM) depreciation based on statutory useful asset life.
B4: 1. FIXED ASSET ALLOCATION & CAPITALISATION BASE (₹ in Crore)
B5: Cost Component | C5: Total Cost | D5: Building Base | E5: Equipment Base | F5: Land Base
B6: =Assumptions!B44 | C6: ='Project Cost & Finance'!C6 | D6: =IF(Assumptions!E44="building", C6, IF(Assumptions!E44="shared", C6*Assumptions!F44, 0)) | E6: =IF(Assumptions!E44="equipment", C6, IF(Assumptions!E44="shared", C6*(1-Assumptions!F44), 0)) | F6: =IF(Assumptions!E44="land", C6, 0)
B7: =Assumptions!B45 | C7: ='Project Cost & Finance'!C7 | D7: =IF(Assumptions!E45="building", C7, IF(Assumptions!E45="shared", C7*Assumptions!F45, 0)) | E7: =IF(Assumptions!E45="equipment", C7, IF(Assumptions!E45="shared", C7*(1-Assumptions!F45), 0)) | F7: =IF(Assumptions!E45="land", C7, 0)
B8: =Assumptions!B46 | C8: ='Project Cost & Finance'!C8 | D8: =IF(Assumptions!E46="building", C8, IF(Assumptions!E46="shared", C8*Assumptions!F46, 0)) | E8: =IF(Assumptions!E46="equipment", C8, IF(Assumptions!E46="shared", C8*(1-Assumptions!F46), 0)) | F8: =IF(Assumptions!E46="land", C8, 0)
B9: =Assumptions!B47 | C9: ='Project Cost & Finance'!C9 | D9: =IF(Assumptions!E47="building", C9, IF(Assumptions!E47="shared", C9*Assumptions!F47, 0)) | E9: =IF(Assumptions!E47="equipment", C9, IF(Assumptions!E47="shared", C9*(1-Assumptions!F47), 0)) | F9: =IF(Assumptions!E47="land", C9, 0)
B10: =Assumptions!B48 | C10: ='Project Cost & Finance'!C10 | D10: =IF(Assumptions!E48="building", C10, IF(Assumptions!E48="shared", C10*Assumptions!F48, 0)) | E10: =IF(Assumptions!E48="equipment", C10, IF(Assumptions!E48="shared", C10*(1-Assumptions!F48), 0)) | F10: =IF(Assumptions!E48="land", C10, 0)
B11: Interest During Construction (IDC) | C11: ='Project Cost & Finance'!C12 | D11: =C11/2 | E11: =C11/2 | F11: 0
B12: Total Capitalised Fixed Asset Base | C12: =SUM(C6:C11) | D12: =SUM(D6:D11) | E12: =SUM(E6:E11) | F12: =SUM(F6:F11)
B14: 2. ANNUAL DEPRECIATION COMPUTATION (SLM)
B15: Asset Class | C15: Asset Base (₹ in Crore) | D15: Useful Life (Yrs) | E15: Annual Depreciation (₹ in Crore)
B16: Hotel Building & Civil Infrastructure | C16: =D12 | D16: =Assumptions!$C$31 | E16: =C16/D16
B17: Plant, Machinery & Kitchen Equipment | C17: =E12 | D17: =Assumptions!$C$32 | E17: =C17/D17
B18: Total Annual Depreciation Charge | C18: =C16+C17 | D18: - | E18: =E16+E17
B20: 3. 10-YEAR FIXED ASSET & DEPRECIATION SCHEDULE (₹ in Crore)
B21: Particulars | C21: Y1 (FY2026) | D21: Y2 (FY2027) | E21: Y3 (FY2028) | F21: Y4 (FY2029) | G21: Y5 (FY2030) | H21: Y6 (FY2031) | I21: Y7 (FY2032) | J21: Y8 (FY2033) | K21: Y9 (FY2034) | L21: Y10 (FY2035)
B22: Gross Block (Original Cost) | C22: =$C$12 | D22: =$C$12 | E22: =$C$12 | F22: =$C$12 | G22: =$C$12 | H22: =$C$12 | I22: =$C$12 | J22: =$C$12 | ... L22: =$C$12
B23: Opening Accumulated Depreciation | C23: 0 | D23: =C25 | E23: =D25 | F23: =E25 | G23: =F25 | H23: =G25 | I23: =H25 | J23: =I25 | K23: =J25 | L23: =K25
B24: Depreciation Charge for the Year | C24: =$E$18 | D24: =$E$18 | E24: =$E$18 | F24: =$E$18 | G24: =$E$18 | H24: =$E$18 | I24: =$E$18 | J24: =$E$18 | ... L24: =$E$18
B25: Closing Accumulated Depreciation | C25: =C23+C24 | D25: =D23+D24 | E25: =E23+E24 | F25: =F23+F24 | G25: =G23+G24 | H25: =H23+H24 | I25: =I23+I24 | J25: =J23+J24 | ... L25: =L23+L24
B26: Net Block (Closing Written Down Value) | C26: =C22-C25 | D26: =D22-D25 | E26: =E22-E25 | F26: =F22-F25 | G26: =G22-G25 | H26: =H22-H25 | I26: =I22-I25 | J26: =J22-J25 | ... L26: =L22-L25

Sheet Loan Repayment Schedule
B1: TERM LOAN REPAYMENT SCHEDULE & INTEREST BURDEN (₹ in Crore)
B2: Amortization schedule linked to sanction terms and stepped repayment profile.
B4: TERM LOAN REPAYMENT & DEBT SERVICE OBLIGATION (₹ in Crore)
B5: Particulars | C5: Y1 (FY2026) | D5: Y2 (FY2027) | E5: Y3 (FY2028) | F5: Y4 (FY2029) | G5: Y5 (FY2030) | H5: Y6 (FY2031) | I5: Y7 (FY2032) | J5: Y8 (FY2033) | K5: Y9 (FY2034) | L5: Y10 (FY2035) | M5: Total
B6: Total Term Loan Sanctioned (Bank Finance) | C6: ='Project Cost & Finance'!$F$13
B7: Annual Principal Repayment Percentage | C7: =Assumptions!C$40 | D7: =Assumptions!D$40 | E7: =Assumptions!E$40 | F7: =Assumptions!F$40 | G7: =Assumptions!G$40 | H7: =Assumptions!H$40 | I7: =Assumptions!I$40 | J7: =Assumptions!J$40 | ... L7: =Assumptions!L$40 | M7: =SUM(C7:L7)
B8: Opening Debt Balance | C8: =C6 | D8: =C10 | E8: =D10 | F8: =E10 | G8: =F10 | H8: =G10 | I8: =H10 | J8: =I10 | K8: =J10 | L8: =K10 | M8: -
B9: [-] Principal Repayment during Year | C9: =$C$6*C7 | D9: =$C$6*D7 | E9: =$C$6*E7 | F9: =$C$6*F7 | G9: =$C$6*G7 | H9: =$C$6*H7 | I9: =$C$6*I7 | J9: =$C$6*J7 | ... L9: =$C$6*L7 | M9: =SUM(C9:L9)
B10: Closing Debt Balance | C10: =C8-C9 | D10: =D8-D9 | E10: =E8-E9 | F10: =F8-F9 | G10: =G8-G9 | H10: =H8-H9 | I10: =I8-I9 | J10: =J8-J9 | ... L10: =L8-L9 | M10: =L10
B11: Average Debt Balance | C11: =(C8+C10)/2 | D11: =(D8+D10)/2 | E11: =(E8+E10)/2 | F11: =(F8+F10)/2 | G11: =(G8+G10)/2 | H11: =(H8+H10)/2 | I11: =(I8+I10)/2 | J11: =(J8+J10)/2 | ... L11: =(L8+L10)/2 | M11: -
B12: Interest on Term Loan (Finance Cost) | C12: =C8*Assumptions!$C$34 | D12: =D8*Assumptions!$C$34 | E12: =E8*Assumptions!$C$34 | F12: =F8*Assumptions!$C$34 | G12: =G8*Assumptions!$C$34 | H12: =H8*Assumptions!$C$34 | I12: =I8*Assumptions!$C$34 | J12: =J8*Assumptions!$C$34 | ... L12: =L8*Assumptions!$C$34 | M12: =SUM(C12:L12)
B13: Total Debt Service Obligation (Principal + Interest) | C13: =C9+C12 | D13: =D9+D12 | E13: =E9+E12 | F13: =F9+F12 | G13: =G9+G12 | H13: =H9+H12 | I13: =I9+I12 | J13: =J9+J12 | ... L13: =L9+L12 | M13: =SUM(C13:L13)

Sheet Projected P&L
B1: PROJECTED PROFIT & LOSS STATEMENT (₹ in Crore)
B2: 10-Year operating income statement. Live formulas linked to Assumptions, Depreciation & Debt sheets.
B4: PROJECT OPERATING PERFORMANCE & EARNINGS (₹ in Crore)
B5: Particulars | C5: Y1 (FY2026) | D5: Y2 (FY2027) | E5: Y3 (FY2028) | F5: Y4 (FY2029) | G5: Y5 (FY2030) | H5: Y6 (FY2031) | I5: Y7 (FY2032) | J5: Y8 (FY2033) | K5: Y9 (FY2034) | L5: Y10 (FY2035)
B6: Occupancy Rate Assumed (%) | C6: =Assumptions!$C$14 | D6: =MIN(Assumptions!$C$16, C6+Assumptions!$C$15) | E6: =MIN(Assumptions!$C$16, D6+Assumptions!$C$15) | F6: =MIN(Assumptions!$C$16, E6+Assumptions!$C$15) | G6: =MIN(Assumptions!$C$16, F6+Assumptions!$C$15) | H6: =MIN(Assumptions!$C$16, G6+Assumptions!$C$15) | I6: =MIN(Assumptions!$C$16, H6+Assumptions!$C$15) | J6: =MIN(Assumptions!$C$16, I6+Assumptions!$C$15) | K6: =MIN(Assumptions!$C$16, J6+Assumptions!$C$15) | L6: =MIN(Assumptions!$C$16, K6+Assumptions!$C$15)
B7: Average Room Tariff per Day (₹) | C7: =Assumptions!$C$12 | D7: =C7*(1+Assumptions!$C$13) | E7: =D7*(1+Assumptions!$C$13) | F7: =E7*(1+Assumptions!$C$13) | G7: =F7*(1+Assumptions!$C$13) | H7: =G7*(1+Assumptions!$C$13) | I7: =H7*(1+Assumptions!$C$13) | J7: =I7*(1+Assumptions!$C$13) | K7: =J7*(1+Assumptions!$C$13) | L7: =K7*(1+Assumptions!$C$13)
B8: A. Operating Revenues (₹ in Crore)
B9: Room Revenues | C9: =(Assumptions!$C$8*Assumptions!$C$9*C6*C7)/10000000 | D9: =(Assumptions!$C$8*Assumptions!$C$9*D6*D7)/10000000 | E9: =(Assumptions!$C$8*Assumptions!$C$9*E6*E7)/10000000 | F9: =(Assumptions!$C$8*Assumptions!$C$9*F6*F7)/10000000 | G9: =(Assumptions!$C$8*Assumptions!$C$9*G6*G7)/10000000 | H9: =(Assumptions!$C$8*Assumptions!$C$9*H6*H7)/10000000 | I9: =(Assumptions!$C$8*Assumptions!$C$9*I6*I7)/10000000 | J9: =(Assumptions!$C$8*Assumptions!$C$9*J6*J7)/10000000 | ... L9: =(Assumptions!$C$8*Assumptions!$C$9*L6*L7)/10000000
B10: Food & Beverages (F&B) Revenues | C10: =C9*(Assumptions!$C$18/Assumptions!$C$17) | D10: =D9*(Assumptions!$C$18/Assumptions!$C$17) | E10: =E9*(Assumptions!$C$18/Assumptions!$C$17) | F10: =F9*(Assumptions!$C$18/Assumptions!$C$17) | G10: =G9*(Assumptions!$C$18/Assumptions!$C$17) | H10: =H9*(Assumptions!$C$18/Assumptions!$C$17) | I10: =I9*(Assumptions!$C$18/Assumptions!$C$17) | J10: =J9*(Assumptions!$C$18/Assumptions!$C$17) | ... L10: =L9*(Assumptions!$C$18/Assumptions!$C$17)
B11: Other Operating Income (Banquets, Spa, etc.) | C11: =C9*(Assumptions!$C$19/Assumptions!$C$17) | D11: =D9*(Assumptions!$C$19/Assumptions!$C$17) | E11: =E9*(Assumptions!$C$19/Assumptions!$C$17) | F11: =F9*(Assumptions!$C$19/Assumptions!$C$17) | G11: =G9*(Assumptions!$C$19/Assumptions!$C$17) | H11: =H9*(Assumptions!$C$19/Assumptions!$C$17) | I11: =I9*(Assumptions!$C$19/Assumptions!$C$17) | J11: =J9*(Assumptions!$C$19/Assumptions!$C$17) | ... L11: =L9*(Assumptions!$C$19/Assumptions!$C$17)
B12: Total Operating Revenue [A] | C12: =SUM(C9:C11) | D12: =SUM(D9:D11) | E12: =SUM(E9:E11) | F12: =SUM(F9:F11) | G12: =SUM(G9:G11) | H12: =SUM(H9:H11) | I12: =SUM(I9:I11) | J12: =SUM(J9:J11) | ... L12: =SUM(L9:L11)
B13: B. Variable Operating Expenses (₹ in Crore)
B14: F&B Consumables & Raw Materials | C14: =C12*Assumptions!$C$22 | D14: =D12*Assumptions!$C$22 | E14: =E12*Assumptions!$C$22 | F14: =F12*Assumptions!$C$22 | G14: =G12*Assumptions!$C$22 | H14: =H12*Assumptions!$C$22 | I14: =I12*Assumptions!$C$22 | J14: =J12*Assumptions!$C$22 | ... L14: =L12*Assumptions!$C$22
B15: Staff & Employee Costs | C15: =C12*Assumptions!$C$23 | D15: =D12*Assumptions!$C$23 | E15: =E12*Assumptions!$C$23 | F15: =F12*Assumptions!$C$23 | G15: =G12*Assumptions!$C$23 | H15: =H12*Assumptions!$C$23 | I15: =I12*Assumptions!$C$23 | J15: =J12*Assumptions!$C$23 | ... L15: =L12*Assumptions!$C$23
B16: Power, Fuel & Utility Charges | C16: =C12*Assumptions!$C$24 | D16: =D12*Assumptions!$C$24 | E16: =E12*Assumptions!$C$24 | F16: =F12*Assumptions!$C$24 | G16: =G12*Assumptions!$C$24 | H16: =H12*Assumptions!$C$24 | I16: =I12*Assumptions!$C$24 | J16: =J12*Assumptions!$C$24 | ... L16: =L12*Assumptions!$C$24
B17: Other Variable Operating Overheads | C17: =C12*Assumptions!$C$25 | D17: =D12*Assumptions!$C$25 | E17: =E12*Assumptions!$C$25 | F17: =F12*Assumptions!$C$25 | G17: =G12*Assumptions!$C$25 | H17: =H12*Assumptions!$C$25 | I17: =I12*Assumptions!$C$25 | J17: =J12*Assumptions!$C$25 | ... L17: =L12*Assumptions!$C$25
B18: Marriott Management / Service Fees | C18: =C9*Assumptions!$C$26 | D18: =D9*Assumptions!$C$26 | E18: =E9*Assumptions!$C$26 | F18: =F9*Assumptions!$C$26 | G18: =G9*Assumptions!$C$26 | H18: =H9*Assumptions!$C$26 | I18: =I9*Assumptions!$C$26 | J18: =J9*Assumptions!$C$26 | ... L18: =L9*Assumptions!$C$26
B19: Total Variable Operating Expenses [B] | C19: =SUM(C14:C18) | D19: =SUM(D14:D18) | E19: =SUM(E14:E18) | F19: =SUM(F14:F18) | G19: =SUM(G14:G18) | H19: =SUM(H14:H18) | I19: =SUM(I14:I18) | J19: =SUM(J14:J18) | ... L19: =SUM(L14:L18)
B20: C. Fixed Expenses (₹ in Crore)
B21: Administrative & Selling Overheads | C21: =C12*Assumptions!$C$27 | D21: =C21*(1+Assumptions!$C$28) | E21: =D21*(1+Assumptions!$C$28) | F21: =E21*(1+Assumptions!$C$28) | G21: =F21*(1+Assumptions!$C$28) | H21: =G21*(1+Assumptions!$C$28) | I21: =H21*(1+Assumptions!$C$28) | J21: =I21*(1+Assumptions!$C$28) | K21: =J21*(1+Assumptions!$C$28) | L21: =K21*(1+Assumptions!$C$28)
B22: Depreciation (Straight Line Method) | C22: =Depreciation!C$24 | D22: =Depreciation!D$24 | E22: =Depreciation!E$24 | F22: =Depreciation!F$24 | G22: =Depreciation!G$24 | H22: =Depreciation!H$24 | I22: =Depreciation!I$24 | J22: =Depreciation!J$24 | ... L22: =Depreciation!L$24
B23: Interest on Term Loan (Finance Costs) | C23: ='Loan Repayment Schedule'!C$12 | D23: ='Loan Repayment Schedule'!D$12 | E23: ='Loan Repayment Schedule'!E$12 | F23: ='Loan Repayment Schedule'!F$12 | G23: ='Loan Repayment Schedule'!G$12 | H23: ='Loan Repayment Schedule'!H$12 | I23: ='Loan Repayment Schedule'!I$12 | J23: ='Loan Repayment Schedule'!J$12 | ... L23: ='Loan Repayment Schedule'!L$12
B24: Total Fixed Expenses [C] | C24: =C21+C22+C23 | D24: =D21+D22+D23 | E24: =E21+E22+E23 | F24: =F21+F22+F23 | G24: =G21+G22+G23 | H24: =H21+H22+H23 | I24: =I21+I22+I23 | J24: =J21+J22+J23 | ... L24: =L21+L22+L23
B25: Total Operating Expenditure [D = B + C] | C25: =C19+C24 | D25: =D19+D24 | E25: =E19+E24 | F25: =F19+F24 | G25: =G19+G24 | H25: =H19+H24 | I25: =I19+I24 | J25: =J19+J24 | ... L25: =L19+L24
B26: EBITDA (Earnings before Int, Tax & Deprec) | C26: =C12-C19-C21 | D26: =D12-D19-D21 | E26: =E12-E19-E21 | F26: =F12-F19-F21 | G26: =G12-G19-G21 | H26: =H12-H19-H21 | I26: =I12-I19-I21 | J26: =J12-J19-J21 | ... L26: =L12-L19-L21
B27: Operating Profit (EBIT) | C27: =C26-C22 | D27: =D26-D22 | E27: =E26-E22 | F27: =F26-F22 | G27: =G26-G22 | H27: =H26-H22 | I27: =I26-I22 | J27: =J26-J22 | ... L27: =L26-L22
B28: Net Profit Before Tax (PBT) [E = A - D] | C28: =C12-C25 | D28: =D12-D25 | E28: =E12-E25 | F28: =F12-F25 | G28: =G12-G25 | H28: =H12-H25 | I28: =I12-I25 | J28: =J12-J25 | ... L28: =L12-L25
B29: [-] Provision for Corporate Income Tax | C29: =MAX(0, C28*Assumptions!$C$33) | D29: =MAX(0, D28*Assumptions!$C$33) | E29: =MAX(0, E28*Assumptions!$C$33) | F29: =MAX(0, F28*Assumptions!$C$33) | G29: =MAX(0, G28*Assumptions!$C$33) | H29: =MAX(0, H28*Assumptions!$C$33) | I29: =MAX(0, I28*Assumptions!$C$33) | J29: =MAX(0, J28*Assumptions!$C$33) | ... L29: =MAX(0, L28*Assumptions!$C$33)
B30: Net Profit After Tax (PAT) [F = E - Tax] | C30: =C28-C29 | D30: =D28-D29 | E30: =E28-E29 | F30: =F28-F29 | G30: =G28-G29 | H30: =H28-H29 | I30: =I28-I29 | J30: =J28-J29 | ... L30: =L28-L29

Sheet Projected Balance Sheet
B1: PROJECTED BALANCE SHEET (₹ in Crore)
B2: Financial position at the end of each operating financial year. Fully reconciled and verified.
B4: ASSETS & LIABILITIES (₹ in Crore)
B5: Particulars | C5: Y1 (FY2026) | D5: Y2 (FY2027) | E5: Y3 (FY2028) | F5: Y4 (FY2029) | G5: Y5 (FY2030) | H5: Y6 (FY2031) | I5: Y7 (FY2032) | J5: Y8 (FY2033) | K5: Y9 (FY2034) | L5: Y10 (FY2035)
B6: I. ASSETS
B7: Gross Fixed Assets (Gross Block) | C7: =Depreciation!C$22 | D7: =Depreciation!D$22 | E7: =Depreciation!E$22 | F7: =Depreciation!F$22 | G7: =Depreciation!G$22 | H7: =Depreciation!H$22 | I7: =Depreciation!I$22 | J7: =Depreciation!J$22 | ... L7: =Depreciation!L$22
B8: [-] Accumulated Depreciation | C8: =Depreciation!C$25 | D8: =Depreciation!D$25 | E8: =Depreciation!E$25 | F8: =Depreciation!F$25 | G8: =Depreciation!G$25 | H8: =Depreciation!H$25 | I8: =Depreciation!I$25 | J8: =Depreciation!J$25 | ... L8: =Depreciation!L$25
B9: Net Fixed Assets (Net Block) | C9: =C7-C8 | D9: =D7-D8 | E9: =E7-E8 | F9: =F7-F8 | G9: =G7-G8 | H9: =H7-H8 | I9: =I7-I8 | J9: =J7-J8 | ... L9: =L7-L8
B10: Capital Work-in-Progress (CWIP) | C10: 0 | D10: 0 | E10: 0 | F10: 0 | G10: 0 | H10: 0 | I10: 0 | J10: 0 | K10: 0 | L10: 0
B11: Cash & Bank Balances | C11: ='Cash Flow'!C$13 | D11: ='Cash Flow'!D$13 | E11: ='Cash Flow'!E$13 | F11: ='Cash Flow'!F$13 | G11: ='Cash Flow'!G$13 | H11: ='Cash Flow'!H$13 | I11: ='Cash Flow'!I$13 | J11: ='Cash Flow'!J$13 | ... L11: ='Cash Flow'!L$13
B12: Total Assets | C12: =C9+C10+C11 | D12: =D9+D10+D11 | E12: =E9+E10+E11 | F12: =F9+F10+F11 | G12: =G9+G10+G11 | H12: =H9+H10+H11 | I12: =I9+I10+I11 | J12: =J9+J10+J11 | ... L12: =L9+L10+L11
B13: II. EQUITY & LIABILITIES
B14: Promoter Share Capital / Equity | C14: ='Project Cost & Finance'!$E$13 | D14: ='Project Cost & Finance'!$E$13 | E14: ='Project Cost & Finance'!$E$13 | F14: ='Project Cost & Finance'!$E$13 | G14: ='Project Cost & Finance'!$E$13 | H14: ='Project Cost & Finance'!$E$13 | I14: ='Project Cost & Finance'!$E$13 | J14: ='Project Cost & Finance'!$E$13 | ... L14: ='Project Cost & Finance'!$E$13
B15: Reserves & Surplus (Accumulated Retained Earnings) | C15: ='Projected P&L'!C$30 | D15: =C15+'Projected P&L'!D$30 | E15: =D15+'Projected P&L'!E$30 | F15: =E15+'Projected P&L'!F$30 | G15: =F15+'Projected P&L'!G$30 | H15: =G15+'Projected P&L'!H$30 | I15: =H15+'Projected P&L'!I$30 | J15: =I15+'Projected P&L'!J$30 | K15: =J15+'Projected P&L'!K$30 | L15: =K15+'Projected P&L'!L$30
B16: Total Net Worth (Shareholders' Funds) | C16: =C14+C15 | D16: =D14+D15 | E16: =E14+E15 | F16: =F14+F15 | G16: =G14+G15 | H16: =H14+H15 | I16: =I14+I15 | J16: =J14+J15 | ... L16: =L14+L15
B17: Bank Term Loan (Outstanding Non-Current Debt) | C17: ='Loan Repayment Schedule'!C$10 | D17: ='Loan Repayment Schedule'!D$10 | E17: ='Loan Repayment Schedule'!E$10 | F17: ='Loan Repayment Schedule'!F$10 | G17: ='Loan Repayment Schedule'!G$10 | H17: ='Loan Repayment Schedule'!H$10 | I17: ='Loan Repayment Schedule'!I$10 | J17: ='Loan Repayment Schedule'!J$10 | ... L17: ='Loan Repayment Schedule'!L$10
B18: Total Liabilities & Net Worth | C18: =C16+C17 | D18: =D16+D17 | E18: =E16+E17 | F18: =F16+F17 | G18: =G16+G17 | H18: =H16+H17 | I18: =I16+I17 | J18: =J16+J17 | ... L18: =L16+L17
B19: Balance Sheet Check (Total Assets - Total Liabilities) | C19: =C12-C18 | D19: =D12-D18 | E19: =E12-E18 | F19: =F12-F18 | G19: =G12-G18 | H19: =H12-H18 | I19: =I12-I18 | J19: =J12-J18 | ... L19: =L12-L18
B20: Audit Verification Status | C20: =IF(ABS(C19)<0.01, "0.00 (TALLIES)", "DISCREPANCY") | D20: =IF(ABS(D19)<0.01, "0.00 (TALLIES)", "DISCREPANCY") | E20: =IF(ABS(E19)<0.01, "0.00 (TALLIES)", "DISCREPANCY") | F20: =IF(ABS(F19)<0.01, "0.00 (TALLIES)", "DISCREPANCY") | G20: =IF(ABS(G19)<0.01, "0.00 (TALLIES)", "DISCREPANCY") | H20: =IF(ABS(H19)<0.01, "0.00 (TALLIES)", "DISCREPANCY") | I20: =IF(ABS(I19)<0.01, "0.00 (TALLIES)", "DISCREPANCY") | J20: =IF(ABS(J19)<0.01, "0.00 (TALLIES)", "DISCREPANCY") | ... L20: =IF(ABS(L19)<0.01, "0.00 (TALLIES)", "DISCREPANCY")

Sheet Cash Flow
B1: PROJECTED CASH FLOW STATEMENT (₹ in Crore)
B2: Operating and financing cash reconciliation. Closing cash balance links to Balance Sheet.
B4: CASH FLOW STATEMENT (₹ in Crore)
B5: Particulars | C5: Y1 (FY2026) | D5: Y2 (FY2027) | E5: Y3 (FY2028) | F5: Y4 (FY2029) | G5: Y5 (FY2030) | H5: Y6 (FY2031) | I5: Y7 (FY2032) | J5: Y8 (FY2033) | K5: Y9 (FY2034) | L5: Y10 (FY2035)
B6: I. CASH FLOW FROM OPERATING ACTIVITIES
B7: Net Profit After Tax (PAT) | C7: ='Projected P&L'!C$30 | D7: ='Projected P&L'!D$30 | E7: ='Projected P&L'!E$30 | F7: ='Projected P&L'!F$30 | G7: ='Projected P&L'!G$30 | H7: ='Projected P&L'!H$30 | I7: ='Projected P&L'!I$30 | J7: ='Projected P&L'!J$30 | ... L7: ='Projected P&L'!L$30
B8: [+] Non-Cash Depreciation Added Back | C8: =Depreciation!C$24 | D8: =Depreciation!D$24 | E8: =Depreciation!E$24 | F8: =Depreciation!F$24 | G8: =Depreciation!G$24 | H8: =Depreciation!H$24 | I8: =Depreciation!I$24 | J8: =Depreciation!J$24 | ... L8: =Depreciation!L$24
B9: Operating Cash Flow [A] | C9: =C7+C8 | D9: =D7+D8 | E9: =E7+E8 | F9: =F7+F8 | G9: =G7+G8 | H9: =H7+H8 | I9: =I7+I8 | J9: =J7+J8 | ... L9: =L7+L8
B10: II. CASH FLOW FROM FINANCING ACTIVITIES
B11: [-] Term Loan Principal Repayment | C11: =-'Loan Repayment Schedule'!C$9 | D11: =-'Loan Repayment Schedule'!D$9 | E11: =-'Loan Repayment Schedule'!E$9 | F11: =-'Loan Repayment Schedule'!F$9 | G11: =-'Loan Repayment Schedule'!G$9 | H11: =-'Loan Repayment Schedule'!H$9 | I11: =-'Loan Repayment Schedule'!I$9 | J11: =-'Loan Repayment Schedule'!J$9 | ... L11: =-'Loan Repayment Schedule'!L$9
B12: Net Cash Surplus / (Deficit) for the Year [A + B] | C12: =C9+C11 | D12: =D9+D11 | E12: =E9+E11 | F12: =F9+F11 | G12: =G9+G11 | H12: =H9+H11 | I12: =I9+I11 | J12: =J9+J11 | ... L12: =L9+L11
B13: Closing Cash & Bank Balance | C13: =C12 | D13: =C13+D12 | E13: =D13+E12 | F13: =E13+F12 | G13: =F13+G12 | H13: =G13+H12 | I13: =H13+I12 | J13: =I13+J12 | K13: =J13+K12 | L13: =K13+L12

Sheet Ratios & DSCR
B1: BANKING RATIOS, DEBT SERVICE COVERAGE (DSCR) & CHARTS
B2: Key bank appraisal viability indicators and coverage trends.
B4: 1. DEBT SERVICE COVERAGE RATIO (DSCR) SCHEDULE (₹ in Crore)
B5: Particulars | C5: Y1 | D5: Y2 | E5: Y3 | F5: Y4 | G5: Y5 | H5: Y6 | I5: Y7 | J5: Y8 | K5: Y9 | L5: Y10 | M5: Average / Benchmark
B6: Net Profit After Tax (PAT) | C6: ='Projected P&L'!C$30 | D6: ='Projected P&L'!D$30 | E6: ='Projected P&L'!E$30 | F6: ='Projected P&L'!F$30 | G6: ='Projected P&L'!G$30 | H6: ='Projected P&L'!H$30 | I6: ='Projected P&L'!I$30 | J6: ='Projected P&L'!J$30 | ... L6: ='Projected P&L'!L$30 | M6: =AVERAGE(C6:L6)
B7: [+] Depreciation for the Year | C7: =Depreciation!C$24 | D7: =Depreciation!D$24 | E7: =Depreciation!E$24 | F7: =Depreciation!F$24 | G7: =Depreciation!G$24 | H7: =Depreciation!H$24 | I7: =Depreciation!I$24 | J7: =Depreciation!J$24 | ... L7: =Depreciation!L$24 | M7: =AVERAGE(C7:L7)
B8: [+] Interest on Term Loan | C8: ='Loan Repayment Schedule'!C$12 | D8: ='Loan Repayment Schedule'!D$12 | E8: ='Loan Repayment Schedule'!E$12 | F8: ='Loan Repayment Schedule'!F$12 | G8: ='Loan Repayment Schedule'!G$12 | H8: ='Loan Repayment Schedule'!H$12 | I8: ='Loan Repayment Schedule'!I$12 | J8: ='Loan Repayment Schedule'!J$12 | ... L8: ='Loan Repayment Schedule'!L$12 | M8: =AVERAGE(C8:L8)
B9: Cash Available for Debt Service (CADS) | C9: =C6+C7+C8 | D9: =D6+D7+D8 | E9: =E6+E7+E8 | F9: =F6+F7+F8 | G9: =G6+G7+G8 | H9: =H6+H7+H8 | I9: =I6+I7+I8 | J9: =J6+J7+J8 | ... L9: =L6+L7+L8 | M9: =AVERAGE(C9:L9)
B10: Principal Repayment Installment | C10: ='Loan Repayment Schedule'!C$9 | D10: ='Loan Repayment Schedule'!D$9 | E10: ='Loan Repayment Schedule'!E$9 | F10: ='Loan Repayment Schedule'!F$9 | G10: ='Loan Repayment Schedule'!G$9 | H10: ='Loan Repayment Schedule'!H$9 | I10: ='Loan Repayment Schedule'!I$9 | J10: ='Loan Repayment Schedule'!J$9 | ... L10: ='Loan Repayment Schedule'!L$9 | M10: =AVERAGE(C10:L10)
B11: Total Debt Service Obligation (Principal + Interest) | C11: =C10+C8 | D11: =D10+D8 | E11: =E10+E8 | F11: =F10+F8 | G11: =G10+G8 | H11: =H10+H8 | I11: =I10+I8 | J11: =J10+J8 | ... L11: =L10+L8 | M11: =AVERAGE(C11:L11)
B12: Debt Service Coverage Ratio (DSCR) [Times] | C12: =C9/C11 | D12: =D9/D11 | E12: =E9/E11 | F12: =F9/F11 | G12: =G9/G11 | H12: =H9/H11 | I12: =I9/I11 | J12: =J9/J11 | ... L12: =L9/L11 | M12: =AVERAGE(C12:L12)
B14: 2. KEY FINANCIAL RATIOS & VIABILITY BENCHMARKS
B15: Interest Coverage Ratio (EBIT / Interest) | C15: ='Projected P&L'!C$27/'Loan Repayment Schedule'!C$12 | D15: ='Projected P&L'!D$27/'Loan Repayment Schedule'!D$12 | E15: ='Projected P&L'!E$27/'Loan Repayment Schedule'!E$12 | F15: ='Projected P&L'!F$27/'Loan Repayment Schedule'!F$12 | G15: ='Projected P&L'!G$27/'Loan Repayment Schedule'!G$12 | H15: ='Projected P&L'!H$27/'Loan Repayment Schedule'!H$12 | I15: ='Projected P&L'!I$27/'Loan Repayment Schedule'!I$12 | J15: ='Projected P&L'!J$27/'Loan Repayment Schedule'!J$12 | ... L15: ='Projected P&L'!L$27/'Loan Repayment Schedule'!L$12 | M15: =AVERAGE(C15:L15)
B16: Debt-Equity Ratio (Term Loan / Net Worth) | C16: ='Projected Balance Sheet'!C$17/'Projected Balance Sheet'!C$16 | D16: ='Projected Balance Sheet'!D$17/'Projected Balance Sheet'!D$16 | E16: ='Projected Balance Sheet'!E$17/'Projected Balance Sheet'!E$16 | F16: ='Projected Balance Sheet'!F$17/'Projected Balance Sheet'!F$16 | G16: ='Projected Balance Sheet'!G$17/'Projected Balance Sheet'!G$16 | H16: ='Projected Balance Sheet'!H$17/'Projected Balance Sheet'!H$16 | I16: ='Projected Balance Sheet'!I$17/'Projected Balance Sheet'!I$16 | J16: ='Projected Balance Sheet'!J$17/'Projected Balance Sheet'!J$16 | ... L16: ='Projected Balance Sheet'!L$17/'Projected Balance Sheet'!L$16 | M16: =AVERAGE(C16:L16)
B17: Net Profit Margin (% of Total Revenue) | C17: ='Projected P&L'!C$30/'Projected P&L'!C$12 | D17: ='Projected P&L'!D$30/'Projected P&L'!D$12 | E17: ='Projected P&L'!E$30/'Projected P&L'!E$12 | F17: ='Projected P&L'!F$30/'Projected P&L'!F$12 | G17: ='Projected P&L'!G$30/'Projected P&L'!G$12 | H17: ='Projected P&L'!H$30/'Projected P&L'!H$12 | I17: ='Projected P&L'!I$30/'Projected P&L'!I$12 | J17: ='Projected P&L'!J$30/'Projected P&L'!J$12 | ... L17: ='Projected P&L'!L$30/'Projected P&L'!L$12 | M17: =AVERAGE(C17:L17)
B18: Operating EBITDA Margin (%) | C18: ='Projected P&L'!C$26/'Projected P&L'!C$12 | D18: ='Projected P&L'!D$26/'Projected P&L'!D$12 | E18: ='Projected P&L'!E$26/'Projected P&L'!E$12 | F18: ='Projected P&L'!F$26/'Projected P&L'!F$12 | G18: ='Projected P&L'!G$26/'Projected P&L'!G$12 | H18: ='Projected P&L'!H$26/'Projected P&L'!H$12 | I18: ='Projected P&L'!I$26/'Projected P&L'!I$12 | J18: ='Projected P&L'!J$26/'Projected P&L'!J$12 | ... L18: ='Projected P&L'!L$26/'Projected P&L'!L$12 | M18: =AVERAGE(C18:L18)
B19: Return on Net Worth (ROE / RONW %) | C19: ='Projected P&L'!C$30/'Projected Balance Sheet'!C$16 | D19: ='Projected P&L'!D$30/'Projected Balance Sheet'!D$16 | E19: ='Projected P&L'!E$30/'Projected Balance Sheet'!E$16 | F19: ='Projected P&L'!F$30/'Projected Balance Sheet'!F$16 | G19: ='Projected P&L'!G$30/'Projected Balance Sheet'!G$16 | H19: ='Projected P&L'!H$30/'Projected Balance Sheet'!H$16 | I19: ='Projected P&L'!I$30/'Projected Balance Sheet'!I$16 | J19: ='Projected P&L'!J$30/'Projected Balance Sheet'!J$16 | ... L19: ='Projected P&L'!L$30/'Projected Balance Sheet'!L$16 | M19: =AVERAGE(C19:L19)
B21: Chart Data Table
B22: Metric | C22: Y1 | D22: Y2 | E22: Y3 | F22: Y4 | G22: Y5 | H22: Y6 | I22: Y7 | J22: Y8 | K22: Y9 | L22: Y10
B23: Revenue | C23: ='Projected P&L'!C$12 | D23: ='Projected P&L'!D$12 | E23: ='Projected P&L'!E$12 | F23: ='Projected P&L'!F$12 | G23: ='Projected P&L'!G$12 | H23: ='Projected P&L'!H$12 | I23: ='Projected P&L'!I$12 | J23: ='Projected P&L'!J$12 | ... L23: ='Projected P&L'!L$12
B24: PAT | C24: ='Projected P&L'!C$30 | D24: ='Projected P&L'!D$30 | E24: ='Projected P&L'!E$30 | F24: ='Projected P&L'!F$30 | G24: ='Projected P&L'!G$30 | H24: ='Projected P&L'!H$30 | I24: ='Projected P&L'!I$30 | J24: ='Projected P&L'!J$30 | ... L24: ='Projected P&L'!L$30
B25: DSCR | C25: =C12 | D25: =D12 | E25: =E12 | F25: =F12 | G25: =G12 | H25: =H12 | I25: =I12 | J25: =J12 | ... L25: =L12

Sheet Break-even
B1: BREAK-EVEN POINT (BEP) & MARGIN OF SAFETY ANALYSIS (₹ in Crore)
B2: Cost-Volume-Profit (CVP) analysis over 10-year projection horizon.
B4: BREAK-EVEN CAPACITY & SENSITIVITY ANALYSIS (₹ in Crore)
B5: Particulars | C5: Y1 (FY2026) | D5: Y2 (FY2027) | E5: Y3 (FY2028) | F5: Y4 (FY2029) | G5: Y5 (FY2030) | H5: Y6 (FY2031) | I5: Y7 (FY2032) | J5: Y8 (FY2033) | K5: Y9 (FY2034) | L5: Y10 (FY2035)
B6: Total Operating Revenue [A] | C6: ='Projected P&L'!C$12 | D6: ='Projected P&L'!D$12 | E6: ='Projected P&L'!E$12 | F6: ='Projected P&L'!F$12 | G6: ='Projected P&L'!G$12 | H6: ='Projected P&L'!H$12 | I6: ='Projected P&L'!I$12 | J6: ='Projected P&L'!J$12 | ... L6: ='Projected P&L'!L$12
B7: [-] Total Variable Costs [B] | C7: ='Projected P&L'!C$19 | D7: ='Projected P&L'!D$19 | E7: ='Projected P&L'!E$19 | F7: ='Projected P&L'!F$19 | G7: ='Projected P&L'!G$19 | H7: ='Projected P&L'!H$19 | I7: ='Projected P&L'!I$19 | J7: ='Projected P&L'!J$19 | ... L7: ='Projected P&L'!L$19
B8: Contribution [C = A - B] | C8: =C6-C7 | D8: =D6-D7 | E8: =E6-E7 | F8: =F6-F7 | G8: =G6-G7 | H8: =H6-H7 | I8: =I6-I7 | J8: =J6-J7 | ... L8: =L6-L7
B9: Profit Volume (PV) Ratio [Contribution % of Sales] | C9: =C8/C6 | D9: =D8/D6 | E9: =E8/E6 | F9: =F8/F6 | G9: =G8/G6 | H9: =H8/H6 | I9: =I8/I6 | J9: =J8/J6 | ... L9: =L8/L6
B10: Fixed Costs (Admin + Depreciation + Interest) | C10: ='Projected P&L'!C$24 | D10: ='Projected P&L'!D$24 | E10: ='Projected P&L'!E$24 | F10: ='Projected P&L'!F$24 | G10: ='Projected P&L'!G$24 | H10: ='Projected P&L'!H$24 | I10: ='Projected P&L'!I$24 | J10: ='Projected P&L'!J$24 | ... L10: ='Projected P&L'!L$24
B11: Break-Even Sales Revenue (₹ in Crore) [Fixed / PV] | C11: =C10/C9 | D11: =D10/D9 | E11: =E10/E9 | F11: =F10/F9 | G11: =G10/G9 | H11: =H10/H9 | I11: =I10/I9 | J11: =J10/J9 | ... L11: =L10/L9
B12: Break-Even Point (% of Operating Revenue) | C12: =C11/C6 | D12: =D11/D6 | E12: =E11/E6 | F12: =F11/F6 | G12: =G11/G6 | H12: =H11/H6 | I12: =I11/I6 | J12: =J11/J6 | ... L12: =L11/L6
B13: Cash Fixed Costs (excluding Depreciation) | C13: =C10-'Projected P&L'!C$22 | D13: =D10-'Projected P&L'!D$22 | E13: =E10-'Projected P&L'!E$22 | F13: =F10-'Projected P&L'!F$22 | G13: =G10-'Projected P&L'!G$22 | H13: =H10-'Projected P&L'!H$22 | I13: =I10-'Projected P&L'!I$22 | J13: =J10-'Projected P&L'!J$22 | ... L13: =L10-'Projected P&L'!L$22
B14: Cash Break-Even Point (% of Sales) | C14: =(C13/C9)/C6 | D14: =(D13/D9)/D6 | E14: =(E13/E9)/E6 | F14: =(F13/F9)/F6 | G14: =(G13/G9)/G6 | H14: =(H13/H9)/H6 | I14: =(I13/I9)/I6 | J14: =(J13/J9)/J6 | ... L14: =(L13/L9)/L6
B15: Margin of Safety (₹ in Crore) [Sales - Break-Even] | C15: =C6-C11 | D15: =D6-D11 | E15: =E6-E11 | F15: =F6-F11 | G15: =G6-G11 | H15: =H6-H11 | I15: =I6-I11 | J15: =J6-J11 | ... L15: =L6-L11
B16: Margin of Safety (% of Operating Revenue) | C16: =C15/C6 | D16: =D15/D6 | E16: =E15/E6 | F16: =F15/F6 | G16: =G15/G6 | H16: =H15/H6 | I16: =I15/I6 | J16: =J15/J6 | ... L16: =L15/L6
