Workbook

Sheet Assumption Sheet
A1: Total Project Cost
A2: Particulars | B2: Total Cost | C2: Margin Requirement | D2: Promoter's Contribution | E2: Bank Finance
B3: Amount in Rs. in Crores / Proportion in %age
A4: Cost of Land [already acquired by the Company] | B4: 20 | C4: 1 | D4: =B4*C4 -> 20 | E4: =B4-D4 -> 0
A5: Cost of Approvals / Premiums & Regulatory Costs | B5: 10 | C5: 0.5 | D5: =B5*C5 -> 5 | E5: =B5-D5 -> 5
A6: Cost of Construction of the Hotel Building | B6: 40 | C6: 0.3 | D6: =B6*C6 -> 12 | E6: =B6-D6 -> 28
A7: Cost of Interiors & Kitchen Equipments | B7: 50 | C7: 0.25 | D7: =B7*C7 -> 12.5 | E7: =B7-D7 -> 37.5
A8: Contingency Margin | B8: 7.5 | C8: 1 | D8: =B8*C8 -> 7.5 | E8: =B8-D8 -> 0
A9: Core Project Cost [A] | B9: =SUM(B4:B8) -> 127.5 | D9: =SUM(D4:D8) -> 57 | E9: =SUM(E4:E8) -> 70.5
A10: Interest During Construction [B] | B10: =J73 -> 7.0775 | C10: 1 | D10: =B10*C10 -> 7.0775 | E10: =B10-D10 -> 0
A11: Total Project Cost [A+B] | B11: =SUM(B9:B10) -> 134.5775 | D11: =SUM(D9:D10) -> 64.0775 | E11: =SUM(E9:E10) -> 70.5
A14: Cost Phasing in %age
A15: Particulars | B15: 2024-25 | F15: 2025-26 | J15: Total
B16: Q I | C16: Q II | D16: Q III | E16: Q IV | F16: Q I | G16: Q II | H16: Q III | I16: Q IV
A17: Cost of Land [already acquired by the Company] | B17: 1 | C17: 0 | D17: 0 | E17: 0 | F17: 0 | G17: 0 | H17: 0 | I17: =J17-SUM(B17:H17) -> 0 | J17: 1
A18: Cost of Approvals / Premiums & Regulatory Costs | B18: 0.25 | C18: 0.5 | D18: 0.1 | E18: 0 | F18: 0 | G18: 0 | H18: 0.1 | I18: =J18-SUM(B18:H18) -> 0.05 | J18: 1
A19: Cost of Construction of the Hotel Building | B19: 0.1 | C19: 0.2 | D19: 0.3 | E19: 0.35 | F19: 0.05 | G19: 0 | H19: 0 | I19: =J19-SUM(B19:H19) -> 0 | J19: 1
A20: Cost of Interiors & Kitchen Equipments | B20: 0 | C20: 0 | D20: 0.1 | E20: 0.1 | F20: 0.2 | G20: 0.2 | H20: 0.3 | I20: =J20-SUM(B20:H20) -> 0.1 | J20: 1
A21: Contingency Margin | B21: 0 | C21: 0 | D21: 0 | E21: 0 | F21: 0 | G21: 0 | H21: 0.5 | I21: =J21-SUM(B21:H21) -> 0.5 | J21: 1
A23: Cost Incurred in Rs.
A24: Particulars | B24: 2024-25 | F24: 2025-26 | J24: Total
B25: Q I | C25: Q II | D25: Q III | E25: Q IV | F25: Q I | G25: Q II | H25: Q III | I25: Q IV
A26: Cost of Land [already acquired by the Company] | B26: =$B$4*B17 -> 20 | C26: =$B$4*C17 -> 0 | D26: =$B$4*D17 -> 0 | E26: =$B$4*E17 -> 0 | F26: =$B$4*F17 -> 0 | G26: =$B$4*G17 -> 0 | H26: =$B$4*H17 -> 0 | I26: =$B$4*I17 -> 0 | J26: =SUM(B26:I26) -> 20
A27: Cost of Approvals / Premiums & Regulatory Costs | B27: =$B$5*B18 -> 2.5 | C27: =$B$5*C18 -> 5 | D27: =$B$5*D18 -> 1 | E27: =$B$5*E18 -> 0 | F27: =$B$5*F18 -> 0 | G27: =$B$5*G18 -> 0 | H27: =$B$5*H18 -> 1 | I27: =$B$5*I18 -> 0.5 | J27: =SUM(B27:I27) -> 10
A28: Cost of Construction of the Hotel Building | B28: =$B$6*B19 -> 4 | C28: =$B$6*C19 -> 8 | D28: =$B$6*D19 -> 12 | E28: =$B$6*E19 -> 14 | F28: =$B$6*F19 -> 2 | G28: =$B$6*G19 -> 0 | H28: =$B$6*H19 -> 0 | I28: =$B$6*I19 -> 0 | J28: =SUM(B28:I28) -> 40
A29: Cost of Interiors & Kitchen Equipments | B29: =$B$7*B20 -> 0 | C29: =$B$7*C20 -> 0 | D29: =$B$7*D20 -> 5 | E29: =$B$7*E20 -> 5 | F29: =$B$7*F20 -> 10 | G29: =$B$7*G20 -> 10 | H29: =$B$7*H20 -> 15 | I29: =$B$7*I20 -> 5 | J29: =SUM(B29:I29) -> 50
A30: Contingency Margin | B30: =$B$8*B21 -> 0 | C30: =$B$8*C21 -> 0 | D30: =$B$8*D21 -> 0 | E30: =$B$8*E21 -> 0 | F30: =$B$8*F21 -> 0 | G30: =$B$8*G21 -> 0 | H30: =$B$8*H21 -> 3.75 | I30: =$B$8*I21 -> 3.75 | J30: =SUM(B30:I30) -> 7.5
A31: Total Cost Incurred | B31: =SUM(B26:B30) -> 26.5 | C31: =SUM(C26:C30) -> 13 | D31: =SUM(D26:D30) -> 18 | E31: =SUM(E26:E30) -> 19 | F31: =SUM(F26:F30) -> 12 | G31: =SUM(G26:G30) -> 10 | H31: =SUM(H26:H30) -> 19.75 | I31: =SUM(I26:I30) -> 9.25 | J31: =SUM(J26:J30) -> 127.5
A34: Term Loan Draw-Down & Promoters Margin requriement
A36: Particulars | B36: 2024-25 | F36: 2025-26 | J36: Total
B37: Q I | C37: Q II | D37: Q III | E37: Q IV | F37: Q I | G37: Q II | H37: Q III | I37: Q IV
A38: Cost of Land [already acquired by the Company]
A39: Promoter's Funding | B39: =B41*$C$4 -> 20 | C39: =C41*$C$4 -> 0 | D39: =D41*$C$4 -> 0 | E39: =E41*$C$4 -> 0 | F39: =F41*$C$4 -> 0 | G39: =G41*$C$4 -> 0 | H39: =H41*$C$4 -> 0 | I39: =I41*$C$4 -> 0 | J39: =SUM(B39:I39) -> 20
A40: Bank Finance | B40: =B41-B39 -> 0 | C40: =C41-C39 -> 0 | D40: =D41-D39 -> 0 | E40: =E41-E39 -> 0 | F40: =F41-F39 -> 0 | G40: =G41-G39 -> 0 | H40: =H41-H39 -> 0 | I40: =I41-I39 -> 0 | J40: =SUM(B40:I40) -> 0
A41: Total Cost of Land | B41: =B26 -> 20 | C41: =C26 -> 0 | D41: =D26 -> 0 | E41: =E26 -> 0 | F41: =F26 -> 0 | G41: =G26 -> 0 | H41: =H26 -> 0 | I41: =I26 -> 0 | J41: =SUM(B41:I41) -> 20
A43: Cost of Approvals / Premiums & Regulatory Costs
A44: Promoter's Funding | B44: =B46*$C$5 -> 1.25 | C44: =C46*$C$5 -> 2.5 | D44: =D46*$C$5 -> 0.5 | E44: =E46*$C$5 -> 0 | F44: =F46*$C$5 -> 0 | G44: =G46*$C$5 -> 0 | H44: =H46*$C$5 -> 0.5 | I44: =I46*$C$5 -> 0.25 | J44: =SUM(B44:I44) -> 5
A45: Bank Finance | B45: =B46-B44 -> 1.25 | C45: =C46-C44 -> 2.5 | D45: =D46-D44 -> 0.5 | E45: =E46-E44 -> 0 | F45: =F46-F44 -> 0 | G45: =G46-G44 -> 0 | H45: =H46-H44 -> 0.5 | I45: =I46-I44 -> 0.25 | J45: =SUM(B45:I45) -> 5
A46: Total Cost of Approvals / Premiums & Regulatory Costs | B46: =B27 -> 2.5 | C46: =C27 -> 5 | D46: =D27 -> 1 | E46: =E27 -> 0 | F46: =F27 -> 0 | G46: =G27 -> 0 | H46: =H27 -> 1 | I46: =I27 -> 0.5 | J46: =SUM(B46:I46) -> 10
A48: Cost of Construction of the Hotel Building
...

Sheet Project Income Statement
A2: Particulars | B2: 2026-27 | C2: 2027-28 | D2: 2028-29 | E2: 2029-30 | F2: 2030-31 | G2: 2031-32 | H2: 2032-33 | I2: 2033-34 | J2: 2034-35 | K2: 2035-36
B3: All Amount in Rs. in Crores
A4: Occupancy Assumed | B4: ='Assumption Sheet'!B97 -> 0.65 | C4: =IF(B4+'Assumption Sheet'!$B$98>=80%,80%,'Project Income Statement'!B4+'Assumption Sheet'!$B$98) -> 0.675 | D4: =IF(C4+'Assumption Sheet'!$B$98>=80%,80%,'Project Income Statement'!C4+'Assumption Sheet'!$B$98) -> 0.7 | E4: =IF(D4+'Assumption Sheet'!$B$98>=80%,80%,'Project Income Statement'!D4+'Assumption Sheet'!$B$98) -> 0.725 | F4: =IF(E4+'Assumption Sheet'!$B$98>=80%,80%,'Project Income Statement'!E4+'Assumption Sheet'!$B$98) -> 0.75 | G4: =IF(F4+'Assumption Sheet'!$B$98>=80%,80%,'Project Income Statement'!F4+'Assumption Sheet'!$B$98) -> 0.775 | H4: =IF(G4+'Assumption Sheet'!$B$98>=80%,80%,'Project Income Statement'!G4+'Assumption Sheet'!$B$98) -> 0.8 | I4: =IF(H4+'Assumption Sheet'!$B$98>=80%,80%,'Project Income Statement'!H4+'Assumption Sheet'!$B$98) -> 0.8 | J4: =IF(I4+'Assumption Sheet'!$B$98>=80%,80%,'Project Income Statement'!I4+'Assumption Sheet'!$B$98) -> 0.8 | K4: =IF(J4+'Assumption Sheet'!$B$98>=80%,80%,'Project Income Statement'!J4+'Assumption Sheet'!$B$98) -> 0.8
A5: Room Tariff per day | B5: ='Assumption Sheet'!B99 -> 10000 | C5: =B5+(B5*'Assumption Sheet'!$B$100) -> 10150 | D5: =C5+(C5*'Assumption Sheet'!$B$100) -> 10302.25 | E5: =D5+(D5*'Assumption Sheet'!$B$100) -> 10456.784 | F5: =E5+(E5*'Assumption Sheet'!$B$100) -> 10613.636 | G5: =F5+(F5*'Assumption Sheet'!$B$100) -> 10772.84 | H5: =G5+(G5*'Assumption Sheet'!$B$100) -> 10934.433 | I5: =H5+(H5*'Assumption Sheet'!$B$100) -> 11098.449 | J5: =I5+(I5*'Assumption Sheet'!$B$100) -> 11264.926 | K5: =J5+(J5*'Assumption Sheet'!$B$100) -> 11433.9
A6: Total Revenues during the Year:
A7: Room revenues | B7: ='Assumption Sheet'!$B$95*'Assumption Sheet'!$B$96*'Project Income Statement'!B4*'Project Income Statement'!B5/10000000 -> 29.65625 | C7: ='Assumption Sheet'!$B$95*'Assumption Sheet'!$B$96*'Project Income Statement'!C4*'Project Income Statement'!C5/10000000 -> 31.258828 | D7: ='Assumption Sheet'!$B$95*'Assumption Sheet'!$B$96*'Project Income Statement'!D4*'Project Income Statement'!D5/10000000 -> 32.902811 | E7: ='Assumption Sheet'!$B$95*'Assumption Sheet'!$B$96*'Project Income Statement'!E4*'Project Income Statement'!E5/10000000 -> 34.58908 | F7: ='Assumption Sheet'!$B$95*'Assumption Sheet'!$B$96*'Project Income Statement'!F4*'Project Income Statement'!F5/10000000 -> 36.318534 | G7: ='Assumption Sheet'!$B$95*'Assumption Sheet'!$B$96*'Project Income Statement'!G4*'Project Income Statement'!G5/10000000 -> 38.092089 | H7: ='Assumption Sheet'!$B$95*'Assumption Sheet'!$B$96*'Project Income Statement'!H4*'Project Income Statement'!H5/10000000 -> 39.910679 | I7: ='Assumption Sheet'!$B$95*'Assumption Sheet'!$B$96*'Project Income Statement'!I4*'Project Income Statement'!I5/10000000 -> 40.509339 | ... K7: ='Assumption Sheet'!$B$95*'Assumption Sheet'!$B$96*'Project Income Statement'!K4*'Project Income Statement'!K5/10000000 -> 41.733734
A8: Food & Beverages | B8: =B7*'Assumption Sheet'!$B$91/'Assumption Sheet'!$B$90 -> 16.176136 | C8: =C7*'Assumption Sheet'!$B$91/'Assumption Sheet'!$B$90 -> 17.05027 | D8: =D7*'Assumption Sheet'!$B$91/'Assumption Sheet'!$B$90 -> 17.946988 | E8: =E7*'Assumption Sheet'!$B$91/'Assumption Sheet'!$B$90 -> 18.866771 | F8: =F7*'Assumption Sheet'!$B$91/'Assumption Sheet'!$B$90 -> 19.810109 | G8: =G7*'Assumption Sheet'!$B$91/'Assumption Sheet'!$B$90 -> 20.777503 | H8: =H7*'Assumption Sheet'!$B$91/'Assumption Sheet'!$B$90 -> 21.769461 | I8: =I7*'Assumption Sheet'!$B$91/'Assumption Sheet'!$B$90 -> 22.096003 | ... K8: =K7*'Assumption Sheet'!$B$91/'Assumption Sheet'!$B$90 -> 22.763855
A9: Other Sources | B9: =B7*'Assumption Sheet'!$B$92/'Assumption Sheet'!$B$90 -> 8.0880682 | C9: =C7*'Assumption Sheet'!$B$92/'Assumption Sheet'!$B$90 -> 8.5251349 | D9: =D7*'Assumption Sheet'!$B$92/'Assumption Sheet'!$B$90 -> 8.9734939 | E9: =E7*'Assumption Sheet'!$B$92/'Assumption Sheet'!$B$90 -> 9.4333855 | F9: =F7*'Assumption Sheet'!$B$92/'Assumption Sheet'!$B$90 -> 9.9050547 | G9: =G7*'Assumption Sheet'!$B$92/'Assumption Sheet'!$B$90 -> 10.388752 | H9: =H7*'Assumption Sheet'!$B$92/'Assumption Sheet'!$B$90 -> 10.884731 | I9: =I7*'Assumption Sheet'!$B$92/'Assumption Sheet'!$B$90 -> 11.048002 | ... K9: =K7*'Assumption Sheet'!$B$92/'Assumption Sheet'!$B$90 -> 11.381927
A10: Total Revenues during the Year [A] | B10: =SUM(B7:B9) -> 53.920455 | C10: =SUM(C7:C9) -> 56.834233 | D10: =SUM(D7:D9) -> 59.823293 | E10: =SUM(E7:E9) -> 62.889236 | F10: =SUM(F7:F9) -> 66.033698 | G10: =SUM(G7:G9) -> 69.258344 | H10: =SUM(H7:H9) -> 72.564871 | I10: =SUM(I7:I9) -> 73.653344 | ... K10: =SUM(K7:K9) -> 75.879517
A11: Total Expenditure for the Year:
A12: Variable Expenses:
A13: Food & Beverages Consumables | B13: =B10*'Assumption Sheet'!$B$105 -> 4.0440341 | C13: =C10*'Assumption Sheet'!$B$105 -> 4.2625675 | D13: =D10*'Assumption Sheet'!$B$105 -> 4.4867469 | E13: =E10*'Assumption Sheet'!$B$105 -> 4.7166927 | F13: =F10*'Assumption Sheet'!$B$105 -> 4.9525274 | G13: =G10*'Assumption Sheet'!$B$105 -> 5.1943758 | H13: =H10*'Assumption Sheet'!$B$105 -> 5.4423653 | I13: =I10*'Assumption Sheet'!$B$105 -> 5.5240008 | ... K13: =K10*'Assumption Sheet'!$B$105 -> 5.6909637
A14: Employee Costs | B14: =B10*'Assumption Sheet'!$B$106 -> 10.784091 | C14: =C10*'Assumption Sheet'!$B$106 -> 11.366847 | D14: =D10*'Assumption Sheet'!$B$106 -> 11.964659 | E14: =E10*'Assumption Sheet'!$B$106 -> 12.577847 | F14: =F10*'Assumption Sheet'!$B$106 -> 13.20674 | G14: =G10*'Assumption Sheet'!$B$106 -> 13.851669 | H14: =H10*'Assumption Sheet'!$B$106 -> 14.512974 | I14: =I10*'Assumption Sheet'!$B$106 -> 14.730669 | ... K14: =K10*'Assumption Sheet'!$B$106 -> 15.175903
A15: Power & Fuel | B15: =B10*'Assumption Sheet'!$B$107 -> 3.2352273 | C15: =C10*'Assumption Sheet'!$B$107 -> 3.410054 | D15: =D10*'Assumption Sheet'!$B$107 -> 3.5893976 | E15: =E10*'Assumption Sheet'!$B$107 -> 3.7733542 | F15: =F10*'Assumption Sheet'!$B$107 -> 3.9620219 | G15: =G10*'Assumption Sheet'!$B$107 -> 4.1555006 | H15: =H10*'Assumption Sheet'!$B$107 -> 4.3538923 | I15: =I10*'Assumption Sheet'!$B$107 -> 4.4192007 | ... K15: =K10*'Assumption Sheet'!$B$107 -> 4.552771
A16: Other Variable Expenses | B16: =B10*'Assumption Sheet'!$B$108 -> 2.1568182 | C16: =C10*'Assumption Sheet'!$B$108 -> 2.2733693 | D16: =D10*'Assumption Sheet'!$B$108 -> 2.3929317 | E16: =E10*'Assumption Sheet'!$B$108 -> 2.5155695 | F16: =F10*'Assumption Sheet'!$B$108 -> 2.6413479 | G16: =G10*'Assumption Sheet'!$B$108 -> 2.7703338 | H16: =H10*'Assumption Sheet'!$B$108 -> 2.9025948 | I16: =I10*'Assumption Sheet'!$B$108 -> 2.9461338 | ... K16: =K10*'Assumption Sheet'!$B$108 -> 3.0351807
A17: Service Fees to Mariott [Room revenue] | B17: =B7*'Assumption Sheet'!$B$109 -> 1.4828125 | C17: =C7*'Assumption Sheet'!$B$109 -> 1.5629414 | D17: =D7*'Assumption Sheet'!$B$109 -> 1.6451405 | E17: =E7*'Assumption Sheet'!$B$109 -> 1.729454 | F17: =F7*'Assumption Sheet'!$B$109 -> 1.8159267 | G17: =G7*'Assumption Sheet'!$B$109 -> 1.9046045 | H17: =H7*'Assumption Sheet'!$B$109 -> 1.995534 | I17: =I7*'Assumption Sheet'!$B$109 -> 2.025467 | ... K17: =K7*'Assumption Sheet'!$B$109 -> 2.0866867
A18: Total Variable Expenses [B] | B18: =SUM(B13:B17) -> 21.702983 | C18: =SUM(C13:C17) -> 22.875779 | D18: =SUM(D13:D17) -> 24.078875 | E18: =SUM(E13:E17) -> 25.312918 | F18: =SUM(F13:F17) -> 26.578564 | G18: =SUM(G13:G17) -> 27.876483 | H18: =SUM(H13:H17) -> 29.207361 | I18: =SUM(I13:I17) -> 29.645471 | ... K18: =SUM(K13:K17) -> 30.541505
A19: Fixed Expenses:
A20: Administrative & Selling Expenses | B20: =B10*'Assumption Sheet'!B112 -> 10.784091 | C20: =B20*(1+'Assumption Sheet'!$B$113) -> 11.8625 | D20: =C20*(1+'Assumption Sheet'!$B$113) -> 13.04875 | E20: =D20*(1+'Assumption Sheet'!$B$113) -> 14.353625 | F20: =E20*(1+'Assumption Sheet'!$B$113) -> 15.788988 | G20: =F20*(1+'Assumption Sheet'!$B$113) -> 17.367886 | H20: =G20*(1+'Assumption Sheet'!$B$113) -> 19.104675 | I20: =H20*(1+'Assumption Sheet'!$B$113) -> 21.015142 | J20: =I20*(1+'Assumption Sheet'!$B$113) -> 23.116657 | K20: =J20*(1+'Assumption Sheet'!$B$113) -> 25.428322
A21: Depreciation | B21: ='Assumption Sheet'!$C$87 -> 5.2514687 | C21: ='Assumption Sheet'!$C$87 -> 5.2514687 | D21: ='Assumption Sheet'!$C$87 -> 5.2514687 | E21: ='Assumption Sheet'!$C$87 -> 5.2514687 | F21: ='Assumption Sheet'!$C$87 -> 5.2514687 | G21: ='Assumption Sheet'!$C$87 -> 5.2514687 | H21: ='Assumption Sheet'!$C$87 -> 5.2514687 | I21: ='Assumption Sheet'!$C$87 -> 5.2514687 | ... K21: ='Assumption Sheet'!$C$87 -> 5.2514687
A22: Interest on Term Loan | B22: =B39 -> 6.961875 | C22: =C39 -> 6.6975 | D22: =D39 -> 6.256875 | E22: =E39 -> 5.64 | F22: =F39 -> 4.846875 | G22: =G39 -> 3.965625 | H22: =H39 -> 3.084375 | I22: =I39 -> 2.203125 | ... K22: =K39 -> 0.440625
A23: Total Fixed Expenses [C] | B23: =SUM(B20:B22) -> 22.997435 | C23: =SUM(C20:C22) -> 23.811469 | D23: =SUM(D20:D22) -> 24.557094 | E23: =SUM(E20:E22) -> 25.245094 | F23: =SUM(F20:F22) -> 25.887331 | G23: =SUM(G20:G22) -> 26.58498 | H23: =SUM(H20:H22) -> 27.440519 | I23: =SUM(I20:I22) -> 28.469736 | ... K23: =SUM(K20:K22) -> 31.120416
A24: Total Expenditure for the Year [D=B+C] | B24: =B23+B18 -> 44.700418 | C24: =C23+C18 -> 46.687248 | D24: =D23+D18 -> 48.635969 | E24: =E23+E18 -> 50.558011 | F24: =F23+F18 -> 52.465895 | G24: =G23+G18 -> 54.461463 | H24: =H23+H18 -> 56.647879 | I24: =I23+I18 -> 58.115207 | ... K24: =K23+K18 -> 61.661921
A25: Net Profit Before Tax [E=A-D] | B25: =B10-B24 -> 9.2200369 | C25: =C10-C24 -> 10.146985 | D25: =D10-D24 -> 11.187324 | E25: =E10-E24 -> 12.331225 | F25: =F10-F24 -> 13.567803 | G25: =G10-G24 -> 14.79688 | H25: =H10-H24 -> 15.916992 | I25: =I10-I24 -> 15.538137 | ... K25: =K10-K24 -> 14.217595
A26: [-] Tax | B26: =B25*'Assumption Sheet'!$B$115 -> 3.0426122 | C26: =C25*'Assumption Sheet'!$B$115 -> 3.3485052 | D26: =D25*'Assumption Sheet'!$B$115 -> 3.6918168 | E26: =E25*'Assumption Sheet'!$B$115 -> 4.0693042 | F26: =F25*'Assumption Sheet'!$B$115 -> 4.4773751 | G26: =G25*'Assumption Sheet'!$B$115 -> 4.8829705 | H26: =H25*'Assumption Sheet'!$B$115 -> 5.2526073 | I26: =I25*'Assumption Sheet'!$B$115 -> 5.1275852 | ... K26: =K25*'Assumption Sheet'!$B$115 -> 4.6918064
A27: Net Profit After Tax | B27: =B25-B26 -> 6.1774247 | C27: =C25-C26 -> 6.7984802 | D27: =D25-D26 -> 7.4955068 | E27: =E25-E26 -> 8.2619207 | F27: =F25-F26 -> 9.0904283 | G27: =G25-G26 -> 9.9139099 | H27: =H25-H26 -> 10.664385 | I27: =I25-I26 -> 10.410552 | ... K27: =K25-K26 -> 9.5257887
A31: Term Loan Repayment Schedule
A32: Particulars | B32: 2026-27 | C32: 2027-28 | D32: 2028-29 | E32: 2029-30 | F32: 2030-31 | G32: 2031-32 | H32: 2032-33 | I32: 2033-34 | J32: 2034-35 | K32: 2035-36
B33: All Amount in Rs. in Crores
A34: Repayment for the Year in %age | B34: 0.025 | C34: 0.05 | D34: 0.075 | E34: 0.1 | F34: 0.125 | G34: 0.125 | H34: 0.125 | I34: 0.125 | J34: 0.125 | K34: =1-SUM(B34:J34) -> 0.125
A35: Opening Balance | B35: ='Assumption Sheet'!E11 -> 70.5 | C35: =B37 -> 68.7375 | D35: =C37 -> 65.2125 | E35: =D37 -> 59.925 | F35: =E37 -> 52.875 | G35: =F37 -> 44.0625 | H35: =G37 -> 35.25 | I35: =H37 -> 26.4375 | J35: =I37 -> 17.625 | K35: =J37 -> 8.8125
A36: [-] Repayment | B36: =$B$35*B34 -> 1.7625 | C36: =$B$35*C34 -> 3.525 | D36: =$B$35*D34 -> 5.2875 | E36: =$B$35*E34 -> 7.05 | F36: =$B$35*F34 -> 8.8125 | G36: =$B$35*G34 -> 8.8125 | H36: =$B$35*H34 -> 8.8125 | I36: =$B$35*I34 -> 8.8125 | ... K36: =$B$35*K34 -> 8.8125
A37: Closing Balance | B37: =B35-B36 -> 68.7375 | C37: =C35-C36 -> 65.2125 | D37: =D35-D36 -> 59.925 | E37: =E35-E36 -> 52.875 | F37: =F35-F36 -> 44.0625 | G37: =G35-G36 -> 35.25 | H37: =H35-H36 -> 26.4375 | I37: =I35-I36 -> 17.625 | ... K37: =K35-K36 -> -1.4210855e-14
A38: Average Balance | B38: =(B35+B37)/2 -> 69.61875 | C38: =(C35+C37)/2 -> 66.975 | D38: =(D35+D37)/2 -> 62.56875 | E38: =(E35+E37)/2 -> 56.4 | F38: =(F35+F37)/2 -> 48.46875 | G38: =(G35+G37)/2 -> 39.65625 | H38: =(H35+H37)/2 -> 30.84375 | I38: =(I35+I37)/2 -> 22.03125 | ... K38: =(K35+K37)/2 -> 4.40625
A39: Interest on Term Loan | B39: =B38*'Assumption Sheet'!$B$75 -> 6.961875 | C39: =C38*'Assumption Sheet'!$B$75 -> 6.6975 | D39: =D38*'Assumption Sheet'!$B$75 -> 6.256875 | E39: =E38*'Assumption Sheet'!$B$75 -> 5.64 | F39: =F38*'Assumption Sheet'!$B$75 -> 4.846875 | G39: =G38*'Assumption Sheet'!$B$75 -> 3.965625 | H39: =H38*'Assumption Sheet'!$B$75 -> 3.084375 | I39: =I38*'Assumption Sheet'!$B$75 -> 2.203125 | ... K39: =K38*'Assumption Sheet'!$B$75 -> 0.440625
A41: Debt Service Coverage Ratio
A42: Particulars | B42: 2026-27 | C42: 2027-28 | D42: 2028-29 | E42: 2029-30 | F42: 2030-31 | G42: 2031-32 | H42: 2032-33 | I42: 2033-34 | J42: 2034-35 | K42: 2035-36
B43: All Amount in Rs. in Crores
A44: Net Profit After tax | B44: =B27 -> 6.1774247 | C44: =C27 -> 6.7984802 | D44: =D27 -> 7.4955068 | E44: =E27 -> 8.2619207 | F44: =F27 -> 9.0904283 | G44: =G27 -> 9.9139099 | H44: =H27 -> 10.664385 | I44: =I27 -> 10.410552 | ... K44: =K27 -> 9.5257887
A45: [+] Interest Payment During the Year | B45: =B22 -> 6.961875 | C45: =C22 -> 6.6975 | D45: =D22 -> 6.256875 | E45: =E22 -> 5.64 | F45: =F22 -> 4.846875 | G45: =G22 -> 3.965625 | H45: =H22 -> 3.084375 | I45: =I22 -> 2.203125 | ... K45: =K22 -> 0.440625
...

Sheet Projected Balance Sheet
A2: Particulars | B2: 2024-25 | C2: 2025-26 | D2: 2026-27 | E2: 2027-28 | F2: 2028-29 | G2: 2029-30 | H2: 2030-31 | I2: 2031-32 | J2: 2032-33 | K2: 2033-34 | L2: 2034-35 | M2: 2035-36
B3: All Amounts in Rs. in Crores
A4: Assets:
A5: Gross Block | B5: 0 | C5: 0 | D5: ='Assumption Sheet'!D121 -> 134.5775 | E5: =D5 -> 134.5775 | F5: =E5 -> 134.5775 | G5: =F5 -> 134.5775 | H5: =G5 -> 134.5775 | I5: =H5 -> 134.5775 | J5: =I5 -> 134.5775 | K5: =J5 -> 134.5775 | L5: =K5 -> 134.5775 | M5: =L5 -> 134.5775
A6: [-] Accumulated Depreciation | B6: 0 | C6: 0 | D6: ='Project Income Statement'!B21 -> 5.2514687 | E6: =D6+'Project Income Statement'!C21 -> 10.502937 | F6: =E6+'Project Income Statement'!D21 -> 15.754406 | G6: =F6+'Project Income Statement'!E21 -> 21.005875 | H6: =G6+'Project Income Statement'!F21 -> 26.257344 | I6: =H6+'Project Income Statement'!G21 -> 31.508813 | J6: =I6+'Project Income Statement'!H21 -> 36.760281 | K6: =J6+'Project Income Statement'!I21 -> 42.01175 | L6: =K6+'Project Income Statement'!J21 -> 47.263219 | M6: =L6+'Project Income Statement'!K21 -> 52.514688
A7: Net Block | B7: =B5-B6 -> 0 | C7: =C5-C6 -> 0 | D7: =D5-D6 -> 129.32603 | E7: =E5-E6 -> 124.07456 | F7: =F5-F6 -> 118.82309 | G7: =G5-G6 -> 113.57162 | H7: =H5-H6 -> 108.32016 | I7: =I5-I6 -> 103.06869 | ... M7: =M5-M6 -> 82.062812
A8: Capital Work in Progress | B8: ='Assumption Sheet'!B121 -> 78.004375 | C8: =B8+'Assumption Sheet'!C121 -> 134.5775 | D8: 0 | E8: 0 | F8: 0 | G8: 0 | H8: 0 | I8: 0 | J8: 0 | K8: 0 | L8: 0 | M8: 0
A9: Cash & Bank Balance | B9: ='Projected Cash FLow Statement'!B16 -> 0 | C9: ='Projected Cash FLow Statement'!C16 -> 0 | D9: ='Projected Cash FLow Statement'!D16 -> 9.6663935 | E9: ='Projected Cash FLow Statement'!E16 -> 18.191342 | F9: ='Projected Cash FLow Statement'!F16 -> 25.650818 | G9: ='Projected Cash FLow Statement'!G16 -> 32.114208 | H9: ='Projected Cash FLow Statement'!H16 -> 37.643605 | I9: ='Projected Cash FLow Statement'!I16 -> 43.996483 | ... M9: ='Projected Cash FLow Statement'!M16 -> 70.388337
A10: Total Assets | B10: =SUM(B7:B9) -> 78.004375 | C10: =SUM(C7:C9) -> 134.5775 | D10: =SUM(D7:D9) -> 138.99242 | E10: =SUM(E7:E9) -> 142.2659 | F10: =SUM(F7:F9) -> 144.47391 | G10: =SUM(G7:G9) -> 145.68583 | H10: =SUM(H7:H9) -> 145.96376 | I10: =SUM(I7:I9) -> 147.06517 | ... M10: =SUM(M7:M9) -> 152.45115
A11: Core Equity Capital | B11: =SUM('Assumption Sheet'!B63:E63)+SUM('Assumption Sheet'!B73:E73) -> 39.654375 | C11: =SUM('Assumption Sheet'!F63:I63)+SUM('Assumption Sheet'!F73:I73)+B11 -> 64.0775 | D11: =C11 -> 64.0775 | E11: =D11 -> 64.0775 | F11: =E11 -> 64.0775 | G11: =F11 -> 64.0775 | H11: =G11 -> 64.0775 | I11: =H11 -> 64.0775 | J11: =I11 -> 64.0775 | K11: =J11 -> 64.0775 | ... M11: =L11 -> 64.0775
A12: [+] Reserves & Surplus | B12: 0 | C12: 0 | D12: ='Project Income Statement'!B27 -> 6.1774247 | E12: =D12+'Project Income Statement'!C27 -> 12.975905 | F12: =E12+'Project Income Statement'!D27 -> 20.471412 | G12: =F12+'Project Income Statement'!E27 -> 28.733333 | H12: =G12+'Project Income Statement'!F27 -> 37.823761 | I12: =H12+'Project Income Statement'!G27 -> 47.737671 | J12: =I12+'Project Income Statement'!H27 -> 58.402055 | K12: =J12+'Project Income Statement'!I27 -> 68.812607 | L12: =K12+'Project Income Statement'!J27 -> 78.847861 | M12: =L12+'Project Income Statement'!K27 -> 88.37365
A13: Net Worth | B13: =SUM(B11:B12) -> 39.654375 | C13: =SUM(C11:C12) -> 64.0775 | D13: =SUM(D11:D12) -> 70.254925 | E13: =SUM(E11:E12) -> 77.053405 | F13: =SUM(F11:F12) -> 84.548912 | G13: =SUM(G11:G12) -> 92.810833 | H13: =SUM(H11:H12) -> 101.90126 | I13: =SUM(I11:I12) -> 111.81517 | ... M13: =SUM(M11:M12) -> 152.45115
A14: Bank Loan | B14: =SUM('Assumption Sheet'!B64:E64) -> 38.35 | C14: =SUM('Assumption Sheet'!F64:I64)+B14 -> 70.5 | D14: ='Project Income Statement'!B37 -> 68.7375 | E14: ='Project Income Statement'!C37 -> 65.2125 | F14: ='Project Income Statement'!D37 -> 59.925 | G14: ='Project Income Statement'!E37 -> 52.875 | H14: ='Project Income Statement'!F37 -> 44.0625 | I14: ='Project Income Statement'!G37 -> 35.25 | J14: ='Project Income Statement'!H37 -> 26.4375 | K14: ='Project Income Statement'!I37 -> 17.625 | ... M14: ='Project Income Statement'!K37 -> -1.4210855e-14
A15: Total Liabilities | B15: =SUM(B13:B14) -> 78.004375 | C15: =SUM(C13:C14) -> 134.5775 | D15: =SUM(D13:D14) -> 138.99242 | E15: =SUM(E13:E14) -> 142.2659 | F15: =SUM(F13:F14) -> 144.47391 | G15: =SUM(G13:G14) -> 145.68583 | H15: =SUM(H13:H14) -> 145.96376 | I15: =SUM(I13:I14) -> 147.06517 | ... M15: =SUM(M13:M14) -> 152.45115
A16: Difference | B16: =B15-B10 -> 0 | C16: =C15-C10 -> 0 | D16: =D15-D10 -> 0 | E16: =E15-E10 -> 0 | F16: =F15-F10 -> 0 | G16: =G15-G10 -> 0 | H16: =H15-H10 -> 0 | I16: =I15-I10 -> 0 | ... M16: =M15-M10 -> 0

Sheet Projected Cash FLow Statement
A2: Particulars | B2: 2024-25 | C2: 2025-26 | D2: 2026-27 | E2: 2027-28 | F2: 2028-29 | G2: 2029-30 | H2: 2030-31 | I2: 2031-32 | J2: 2032-33 | K2: 2033-34 | L2: 2034-35 | M2: 2035-36
B3: All Amounts in Rs. in Crores
A4: Sources of Finance:
A5: Net Profit After Tax | B5: 0 | C5: 0 | D5: ='Project Income Statement'!B27 -> 6.1774247 | E5: ='Project Income Statement'!C27 -> 6.7984802 | F5: ='Project Income Statement'!D27 -> 7.4955068 | G5: ='Project Income Statement'!E27 -> 8.2619207 | H5: ='Project Income Statement'!F27 -> 9.0904283 | I5: ='Project Income Statement'!G27 -> 9.9139099 | J5: ='Project Income Statement'!H27 -> 10.664385 | K5: ='Project Income Statement'!I27 -> 10.410552 | ... M5: ='Project Income Statement'!K27 -> 9.5257887
A6: [+] Depreciation | B6: 0 | C6: 0 | D6: ='Project Income Statement'!B21 -> 5.2514687 | E6: ='Project Income Statement'!C21 -> 5.2514687 | F6: ='Project Income Statement'!D21 -> 5.2514687 | G6: ='Project Income Statement'!E21 -> 5.2514687 | H6: ='Project Income Statement'!F21 -> 5.2514687 | I6: ='Project Income Statement'!G21 -> 5.2514687 | J6: ='Project Income Statement'!H21 -> 5.2514687 | K6: ='Project Income Statement'!I21 -> 5.2514687 | ... M6: ='Project Income Statement'!K21 -> 5.2514687
A7: [+] Capital Infusion | B7: ='Projected Balance Sheet'!B11 -> 39.654375 | C7: ='Projected Balance Sheet'!C11-'Projected Balance Sheet'!B11 -> 24.423125 | D7: 0 | E7: 0 | F7: 0 | G7: 0 | H7: 0 | I7: 0 | J7: 0 | K7: 0 | L7: 0 | M7: 0
A8: [+] Debt Capital Raised | B8: ='Projected Balance Sheet'!B14 -> 38.35 | C8: ='Projected Balance Sheet'!C14-'Projected Balance Sheet'!B14 -> 32.15
A9: Total Funds Infused [A] | B9: =SUM(B5:B8) -> 78.004375 | C9: =SUM(C5:C8) -> 56.573125 | D9: =SUM(D5:D8) -> 11.428893 | E9: =SUM(E5:E8) -> 12.049949 | F9: =SUM(F5:F8) -> 12.746976 | G9: =SUM(G5:G8) -> 13.513389 | H9: =SUM(H5:H8) -> 14.341897 | I9: =SUM(I5:I8) -> 15.165379 | ... M9: =SUM(M5:M8) -> 14.777257
A10: Use of Funds:
A11: Fixed Assets Purchased | B11: =SUM('Assumption Sheet'!B65:E65)+SUM('Assumption Sheet'!B73:E73) -> 78.004375 | C11: =SUM('Assumption Sheet'!F65:I65)+SUM('Assumption Sheet'!F73:I73) -> 56.573125 | D11: 0 | E11: 0 | F11: 0 | G11: 0 | H11: 0 | I11: 0 | J11: 0 | K11: 0 | L11: 0 | M11: 0
A12: Term Loan Repaid | B12: 0 | C12: 0 | D12: ='Project Income Statement'!B36 -> 1.7625 | E12: ='Project Income Statement'!C36 -> 3.525 | F12: ='Project Income Statement'!D36 -> 5.2875 | G12: ='Project Income Statement'!E36 -> 7.05 | H12: ='Project Income Statement'!F36 -> 8.8125 | I12: ='Project Income Statement'!G36 -> 8.8125 | J12: ='Project Income Statement'!H36 -> 8.8125 | K12: ='Project Income Statement'!I36 -> 8.8125 | ... M12: ='Project Income Statement'!K36 -> 8.8125
A13: Total Out-Flow [B] | B13: =SUM(B11:B12) -> 78.004375 | C13: =SUM(C11:C12) -> 56.573125 | D13: =SUM(D11:D12) -> 1.7625 | E13: =SUM(E11:E12) -> 3.525 | F13: =SUM(F11:F12) -> 5.2875 | G13: =SUM(G11:G12) -> 7.05 | H13: =SUM(H11:H12) -> 8.8125 | I13: =SUM(I11:I12) -> 8.8125 | ... M13: =SUM(M11:M12) -> 8.8125
A14: Surplus [A-B] | B14: =B9-B13 -> 0 | C14: =C9-C13 -> 0 | D14: =D9-D13 -> 9.6663935 | E14: =E9-E13 -> 8.524949 | F14: =F9-F13 -> 7.4594756 | G14: =G9-G13 -> 6.4633895 | H14: =H9-H13 -> 5.529397 | I14: =I9-I13 -> 6.3528786 | ... M14: =M9-M13 -> 5.9647575
A15: Opening Balance | B15: 0 | C15: =B16 -> 0 | D15: =C16 -> 0 | E15: =D16 -> 9.6663935 | F15: =E16 -> 18.191342 | G15: =F16 -> 25.650818 | H15: =G16 -> 32.114208 | I15: =H16 -> 37.643605 | J15: =I16 -> 43.996483 | ... M15: =L16 -> 64.42358
A16: Closing Balance | B16: =SUM(B14:B15) -> 0 | C16: =SUM(C14:C15) -> 0 | D16: =SUM(D14:D15) -> 9.6663935 | E16: =SUM(E14:E15) -> 18.191342 | F16: =SUM(F14:F15) -> 25.650818 | G16: =SUM(G14:G15) -> 32.114208 | H16: =SUM(H14:H15) -> 37.643605 | I16: =SUM(I14:I15) -> 43.996483 | ... M16: =SUM(M14:M15) -> 70.388337
